2024-10-29 11:41:51,975 - CRITICAL - Application failed to start: 'NoneType' object has no attribute 'setText'
Traceback (most recent call last):
  File "C:\Users\user\Bigdata\main.py", line 485, in main
    window = MalwareAnalyzer()
             ^^^^^^^^^^^^^^^^^
  File "C:\Users\user\Bigdata\main.py", line 217, in __init__
    self.setup_ui()
  File "C:\Users\user\Bigdata\main.py", line 232, in setup_ui
    self.malware_file.setText("厩己 颇老: No File")
    ^^^^^^^^^^^^^^^^^^^^^^^^^
AttributeError: 'NoneType' object has no attribute 'setText'

2024-10-29 11:42:10,687 - CRITICAL - Application failed to start: 'NoneType' object has no attribute 'setText'
Traceback (most recent call last):
  File "C:\Users\user\Bigdata\main.py", line 485, in main
    window = MalwareAnalyzer()
             ^^^^^^^^^^^^^^^^^
  File "C:\Users\user\Bigdata\main.py", line 217, in __init__
    self.setup_ui()
  File "C:\Users\user\Bigdata\main.py", line 232, in setup_ui
    self.malware_file.setText("厩己 颇老: No File")
    ^^^^^^^^^^^^^^^^^^^^^^^^^
AttributeError: 'NoneType' object has no attribute 'setText'

2024-10-29 11:43:05,134 - CRITICAL - Application failed to start: 'NoneType' object has no attribute 'setText'
Traceback (most recent call last):
  File "C:\Users\user\Bigdata\main.py", line 485, in main
    window = MalwareAnalyzer()
             ^^^^^^^^^^^^^^^^^
  File "C:\Users\user\Bigdata\main.py", line 217, in __init__
    self.setup_ui()
  File "C:\Users\user\Bigdata\main.py", line 232, in setup_ui
    self.malware_file.setText("厩己 颇老: No File")
    ^^^^^^^^^^^^^^^^^^^^^^^^^
AttributeError: 'NoneType' object has no attribute 'setText'

2024-10-29 11:45:55,736 - ERROR - UI Setup Error: 'MalwareAnalyzer' object has no attribute 'start_analysis'
Traceback (most recent call last):
  File "C:\Users\user\Bigdata\main.py", line 230, in setup_ui
    self.train_button.clicked.connect(self.start_analysis)
                                      ^^^^^^^^^^^^^^^^^^^
AttributeError: 'MalwareAnalyzer' object has no attribute 'start_analysis'

2024-10-29 11:45:55,746 - CRITICAL - Application failed to start: 'MalwareAnalyzer' object has no attribute 'start_analysis'
Traceback (most recent call last):
  File "C:\Users\user\Bigdata\main.py", line 487, in main
    window = MalwareAnalyzer()
             ^^^^^^^^^^^^^^^^^
  File "C:\Users\user\Bigdata\main.py", line 217, in __init__
    self.setup_ui()
  File "C:\Users\user\Bigdata\main.py", line 230, in setup_ui
    self.train_button.clicked.connect(self.start_analysis)
                                      ^^^^^^^^^^^^^^^^^^^
AttributeError: 'MalwareAnalyzer' object has no attribute 'start_analysis'

2024-10-29 11:49:39,004 - CRITICAL - Application failed to start: [Errno 2] No such file or directory: 'malware_analyzer.ui'
Traceback (most recent call last):
  File "C:\Users\user\Bigdata\main.py", line 518, in main
    window = MalwareAnalyzer()
             ^^^^^^^^^^^^^^^^^
  File "C:\Users\user\Bigdata\main.py", line 170, in __init__
    uic.loadUi('malware_analyzer.ui', self)
  File "C:\Users\user\AppData\Local\Programs\Python\Python312\Lib\site-packages\PyQt5\uic\__init__.py", line 241, in loadUi
    return DynamicUILoader(package).loadUi(uifile, baseinstance, resource_suffix)
           ^^^^^^^^^^^^^^^^^^^^^^^^^^^^^^^^^^^^^^^^^^^^^^^^^^^^^^^^^^^^^^^^^^^^^^
  File "C:\Users\user\AppData\Local\Programs\Python\Python312\Lib\site-packages\PyQt5\uic\Loader\loader.py", line 66, in loadUi
    return self.parse(filename, resource_suffix)
           ^^^^^^^^^^^^^^^^^^^^^^^^^^^^^^^^^^^^^
  File "C:\Users\user\AppData\Local\Programs\Python\Python312\Lib\site-packages\PyQt5\uic\uiparser.py", line 1020, in parse
    document = parse(filename)
               ^^^^^^^^^^^^^^^
  File "C:\Users\user\AppData\Local\Programs\Python\Python312\Lib\xml\etree\ElementTree.py", line 1204, in parse
    tree.parse(source, parser)
  File "C:\Users\user\AppData\Local\Programs\Python\Python312\Lib\xml\etree\ElementTree.py", line 558, in parse
    source = open(source, "rb")
             ^^^^^^^^^^^^^^^^^^
FileNotFoundError: [Errno 2] No such file or directory: 'malware_analyzer.ui'

2024-10-29 11:51:40,869 - CRITICAL - Failed to initialize application: UI file not found at C:\Users\user\Bigdata\malware_analyzer.ui
Traceback (most recent call last):
  File "C:\Users\user\Bigdata\main.py", line 178, in __init__
    raise FileNotFoundError(f"UI file not found at {ui_file}")
FileNotFoundError: UI file not found at C:\Users\user\Bigdata\malware_analyzer.ui

2024-10-29 11:51:44,364 - CRITICAL - Application failed to start: UI file not found at C:\Users\user\Bigdata\malware_analyzer.ui
Traceback (most recent call last):
  File "C:\Users\user\Bigdata\main.py", line 537, in main
    window = MalwareAnalyzer()
             ^^^^^^^^^^^^^^^^^
  File "C:\Users\user\Bigdata\main.py", line 178, in __init__
    raise FileNotFoundError(f"UI file not found at {ui_file}")
FileNotFoundError: UI file not found at C:\Users\user\Bigdata\malware_analyzer.ui

2024-10-29 11:52:04,201 - CRITICAL - Failed to initialize application: 'MalwareAnalyzer' object has no attribute 'start_analysis'
Traceback (most recent call last):
  File "C:\Users\user\Bigdata\main.py", line 189, in __init__
    self.setup_ui()
  File "C:\Users\user\Bigdata\main.py", line 206, in setup_ui
    self.analyzeBtn.clicked.connect(self.start_analysis)
                                    ^^^^^^^^^^^^^^^^^^^
AttributeError: 'MalwareAnalyzer' object has no attribute 'start_analysis'

2024-10-29 11:52:06,378 - CRITICAL - Application failed to start: 'MalwareAnalyzer' object has no attribute 'start_analysis'
Traceback (most recent call last):
  File "C:\Users\user\Bigdata\main.py", line 537, in main
    window = MalwareAnalyzer()
             ^^^^^^^^^^^^^^^^^
  File "C:\Users\user\Bigdata\main.py", line 189, in __init__
    self.setup_ui()
  File "C:\Users\user\Bigdata\main.py", line 206, in setup_ui
    self.analyzeBtn.clicked.connect(self.start_analysis)
                                    ^^^^^^^^^^^^^^^^^^^
AttributeError: 'MalwareAnalyzer' object has no attribute 'start_analysis'

2024-10-29 12:46:55,710 - CRITICAL - Failed to initialize application: UI file not found at C:\Users\user\Bigdata\malware_analyzer.ui
Traceback (most recent call last):
  File "C:\Users\user\Bigdata\main.py", line 178, in __init__
    raise FileNotFoundError(f"UI file not found at {ui_file}")
FileNotFoundError: UI file not found at C:\Users\user\Bigdata\malware_analyzer.ui

2024-10-29 12:46:58,406 - CRITICAL - Application failed to start: UI file not found at C:\Users\user\Bigdata\malware_analyzer.ui
Traceback (most recent call last):
  File "C:\Users\user\Bigdata\main.py", line 724, in main
    window = MalwareAnalyzer()
             ^^^^^^^^^^^^^^^^^
  File "C:\Users\user\Bigdata\main.py", line 178, in __init__
    raise FileNotFoundError(f"UI file not found at {ui_file}")
FileNotFoundError: UI file not found at C:\Users\user\Bigdata\malware_analyzer.ui

